2021-11-17 23:42:53,493 ERROR -> in command: start
Traceback (most recent call last):
  File "C:\Users\ryanz\AppData\Local\Programs\Python\Python39\lib\site-packages\discord\ext\commands\core.py", line 85, in wrapped
    ret = await coro(*args, **kwargs)
  File "c:\Users\ryanz\OneDrive\Desktop\python projects\tournament-generator\tournament-generator\cogs\Generation.py", line 120, in start
    mes, round, file_content = self.bot.generator_instances[ctx.channel.id].start_tournament()
  File "c:\Users\ryanz\OneDrive\Desktop\python projects\tournament-generator\tournament-generator\classes\Channels.py", line 94, in start_tournament
    player_list = list(map(lambda l: Player(int(l[0]), None if l[3].lower()=="none" else int(l[1]), l[2], None if l[3].lower()=="none" else int(l[3])), player_list)) # convert lists into player objects
  File "c:\Users\ryanz\OneDrive\Desktop\python projects\tournament-generator\tournament-generator\classes\Channels.py", line 94, in <lambda>
    player_list = list(map(lambda l: Player(int(l[0]), None if l[3].lower()=="none" else int(l[1]), l[2], None if l[3].lower()=="none" else int(l[3])), player_list)) # convert lists into player objects
ValueError: invalid literal for int() with base 10: 'None'


2021-11-17 23:47:14,401 ERROR -> in command: nextround
Traceback (most recent call last):
  File "C:\Users\ryanz\AppData\Local\Programs\Python\Python39\lib\site-packages\discord\ext\commands\core.py", line 85, in wrapped
    ret = await coro(*args, **kwargs)
  File "c:\Users\ryanz\OneDrive\Desktop\python projects\tournament-generator\tournament-generator\cogs\Generation.py", line 180, in nextround
    mes, round, file_content = self.bot.generator_instances[ctx.channel.id].next_round()
  File "c:\Users\ryanz\OneDrive\Desktop\python projects\tournament-generator\tournament-generator\classes\Channels.py", line 125, in next_round
    registration_instance.update_round_results(self.generator.get_round_results())
  File "c:\Users\ryanz\OneDrive\Desktop\python projects\tournament-generator\tournament-generator\classes\Channels.py", line 45, in update_round_results
    self.registrator.add_round_results(results)
  File "c:\Users\ryanz\OneDrive\Desktop\python projects\tournament-generator\tournament-generator\classes\registrator.py", line 91, in add_round_results
    title_range, results_range = self.__get_next_results_range(self.res_sheet, len(results_data))
TypeError: __get_next_results_range() takes 2 positional arguments but 3 were given


2021-11-17 23:48:33,457 ERROR -> in command: nextround
Traceback (most recent call last):
  File "C:\Users\ryanz\AppData\Local\Programs\Python\Python39\lib\site-packages\discord\ext\commands\core.py", line 85, in wrapped
    ret = await coro(*args, **kwargs)
  File "c:\Users\ryanz\OneDrive\Desktop\python projects\tournament-generator\tournament-generator\cogs\Generation.py", line 180, in nextround
    mes, round, file_content = self.bot.generator_instances[ctx.channel.id].next_round()
  File "c:\Users\ryanz\OneDrive\Desktop\python projects\tournament-generator\tournament-generator\classes\Channels.py", line 125, in next_round
    registration_instance.update_round_results(self.generator.get_round_results())
  File "c:\Users\ryanz\OneDrive\Desktop\python projects\tournament-generator\tournament-generator\classes\Channels.py", line 45, in update_round_results
    self.registrator.add_round_results(results)
  File "c:\Users\ryanz\OneDrive\Desktop\python projects\tournament-generator\tournament-generator\classes\registrator.py", line 91, in add_round_results
    title_range, results_range = self.__get_next_results_range(len(results_data))
  File "c:\Users\ryanz\OneDrive\Desktop\python projects\tournament-generator\tournament-generator\classes\registrator.py", line 111, in __get_next_results_range
    sheet_vals = self.res_sheet.get_values(major_dimension='COLS')
  File "C:\Users\ryanz\AppData\Local\Programs\Python\Python39\lib\site-packages\gspread\utils.py", line 593, in wrapper
    return f(*args, **kwargs)
  File "C:\Users\ryanz\AppData\Local\Programs\Python\Python39\lib\site-packages\gspread\models.py", line 857, in get_values
    return fill_gaps(self.get(range_name, **kwargs))
  File "C:\Users\ryanz\AppData\Local\Programs\Python\Python39\lib\site-packages\gspread\utils.py", line 593, in wrapper
    return f(*args, **kwargs)
  File "C:\Users\ryanz\AppData\Local\Programs\Python\Python39\lib\site-packages\gspread\models.py", line 1136, in get
    response = self.spreadsheet.values_get(range_name, params=params)
  File "C:\Users\ryanz\AppData\Local\Programs\Python\Python39\lib\site-packages\gspread\models.py", line 221, in values_get
    r = self.client.request('get', url, params=params)
  File "C:\Users\ryanz\AppData\Local\Programs\Python\Python39\lib\site-packages\gspread\client.py", line 76, in request
    raise APIError(response)
gspread.exceptions.APIError: {'code': 400, 'message': 'Invalid value at \'major_dimension\' (type.googleapis.com/google.apps.sheets.v4.Dimension), "COLS"', 'status': 'INVALID_ARGUMENT', 'details': [{'@type': 'type.googleapis.com/google.rpc.BadRequest', 'fieldViolations': [{'field': 'major_dimension', 'description': 'Invalid value at \'major_dimension\' (type.googleapis.com/google.apps.sheets.v4.Dimension), "COLS"'}]}]}


2021-11-17 23:52:35,089 ERROR -> in command: nextround
Traceback (most recent call last):
  File "C:\Users\ryanz\AppData\Local\Programs\Python\Python39\lib\site-packages\discord\ext\commands\core.py", line 85, in wrapped
    ret = await coro(*args, **kwargs)
  File "c:\Users\ryanz\OneDrive\Desktop\python projects\tournament-generator\tournament-generator\cogs\Generation.py", line 180, in nextround
    mes, round, file_content = self.bot.generator_instances[ctx.channel.id].next_round()
  File "c:\Users\ryanz\OneDrive\Desktop\python projects\tournament-generator\tournament-generator\classes\Channels.py", line 125, in next_round
    registration_instance.update_round_results(self.generator.get_round_results())
  File "c:\Users\ryanz\OneDrive\Desktop\python projects\tournament-generator\tournament-generator\classes\generator.py", line 220, in get_round_results
    round_data = self.__round_results(round)
  File "c:\Users\ryanz\OneDrive\Desktop\python projects\tournament-generator\tournament-generator\classes\generator.py", line 227, in __round_results
    for match in self.round_groupings[round]:
IndexError: list index out of range


2021-11-18 00:03:44,864 ERROR -> _ClientEventTask exception was never retrieved
future: <ClientEventTask state=finished event=on_message coro=<bound method BotBase.on_message of <__main__.TournamentBOT object at 0x0000018CFA7E1A60>> exception=RegChannelSetupError()>
Traceback (most recent call last):
  File "C:\Users\ryanz\AppData\Local\Programs\Python\Python39\lib\site-packages\discord\client.py", line 343, in _run_event
    await coro(*args, **kwargs)
  File "C:\Users\ryanz\AppData\Local\Programs\Python\Python39\lib\site-packages\discord\ext\commands\bot.py", line 979, in on_message
    await self.process_commands(message)
  File "C:\Users\ryanz\AppData\Local\Programs\Python\Python39\lib\site-packages\discord\ext\commands\bot.py", line 976, in process_commands
    await self.invoke(ctx)
  File "C:\Users\ryanz\AppData\Local\Programs\Python\Python39\lib\site-packages\discord\ext\commands\bot.py", line 939, in invoke
    await ctx.command.invoke(ctx)
  File "C:\Users\ryanz\AppData\Local\Programs\Python\Python39\lib\site-packages\discord\ext\commands\core.py", line 855, in invoke
    await self.prepare(ctx)
  File "C:\Users\ryanz\AppData\Local\Programs\Python\Python39\lib\site-packages\discord\ext\commands\core.py", line 791, in prepare
    await self.call_before_hooks(ctx)
  File "C:\Users\ryanz\AppData\Local\Programs\Python\Python39\lib\site-packages\discord\ext\commands\core.py", line 739, in call_before_hooks
    await hook(ctx)
  File "c:\Users\ryanz\OneDrive\Desktop\python projects\tournament-generator\tournament-generator\cogs\Registration.py", line 41, in cog_before_invoke
    self.check_instance(ctx)
  File "c:\Users\ryanz\OneDrive\Desktop\python projects\tournament-generator\tournament-generator\cogs\Registration.py", line 38, in check_instance
    raise RegChannelSetupError
classes.Errors.RegChannelSetupError
2021-11-18 00:04:12,423 ERROR -> in command: nextround
Traceback (most recent call last):
  File "C:\Users\ryanz\AppData\Local\Programs\Python\Python39\lib\site-packages\discord\ext\commands\core.py", line 85, in wrapped
    ret = await coro(*args, **kwargs)
  File "c:\Users\ryanz\OneDrive\Desktop\python projects\tournament-generator\tournament-generator\cogs\Generation.py", line 180, in nextround
    mes, round, file_content = self.bot.generator_instances[ctx.channel.id].next_round()
  File "c:\Users\ryanz\OneDrive\Desktop\python projects\tournament-generator\tournament-generator\classes\Channels.py", line 125, in next_round
    registration_instance.update_round_results(self.generator.get_round_results())
  File "c:\Users\ryanz\OneDrive\Desktop\python projects\tournament-generator\tournament-generator\classes\generator.py", line 190, in get_round_results
    if round == -1: round == list(self.round_advancements.keys())[-1] #get last round's results
IndexError: list index out of range


2021-11-18 00:09:43,411 ERROR -> in command: nextround
Traceback (most recent call last):
  File "C:\Users\ryanz\AppData\Local\Programs\Python\Python39\lib\site-packages\discord\ext\commands\core.py", line 85, in wrapped
    ret = await coro(*args, **kwargs)
  File "c:\Users\ryanz\OneDrive\Desktop\python projects\tournament-generator\tournament-generator\cogs\Generation.py", line 180, in nextround
    mes, round, file_content = self.bot.generator_instances[ctx.channel.id].next_round()
  File "c:\Users\ryanz\OneDrive\Desktop\python projects\tournament-generator\tournament-generator\classes\Channels.py", line 125, in next_round
    registration_instance.update_round_results(self.generator.get_round_results())
  File "c:\Users\ryanz\OneDrive\Desktop\python projects\tournament-generator\tournament-generator\classes\generator.py", line 186, in get_round_results
    if round == -1: round = list(self.round_advancements.keys())[-1] #get last round's results
IndexError: list index out of range


2021-11-18 00:11:52,672 ERROR -> _ClientEventTask exception was never retrieved
future: <ClientEventTask state=finished event=on_message coro=<bound method BotBase.on_message of <__main__.TournamentBOT object at 0x0000025908851A30>> exception=RegChannelSetupError()>
Traceback (most recent call last):
  File "C:\Users\ryanz\AppData\Local\Programs\Python\Python39\lib\site-packages\discord\client.py", line 343, in _run_event
    await coro(*args, **kwargs)
  File "C:\Users\ryanz\AppData\Local\Programs\Python\Python39\lib\site-packages\discord\ext\commands\bot.py", line 979, in on_message
    await self.process_commands(message)
  File "C:\Users\ryanz\AppData\Local\Programs\Python\Python39\lib\site-packages\discord\ext\commands\bot.py", line 976, in process_commands
    await self.invoke(ctx)
  File "C:\Users\ryanz\AppData\Local\Programs\Python\Python39\lib\site-packages\discord\ext\commands\bot.py", line 939, in invoke
    await ctx.command.invoke(ctx)
  File "C:\Users\ryanz\AppData\Local\Programs\Python\Python39\lib\site-packages\discord\ext\commands\core.py", line 855, in invoke
    await self.prepare(ctx)
  File "C:\Users\ryanz\AppData\Local\Programs\Python\Python39\lib\site-packages\discord\ext\commands\core.py", line 791, in prepare
    await self.call_before_hooks(ctx)
  File "C:\Users\ryanz\AppData\Local\Programs\Python\Python39\lib\site-packages\discord\ext\commands\core.py", line 739, in call_before_hooks
    await hook(ctx)
  File "c:\Users\ryanz\OneDrive\Desktop\python projects\tournament-generator\tournament-generator\cogs\Registration.py", line 41, in cog_before_invoke
    self.check_instance(ctx)
  File "c:\Users\ryanz\OneDrive\Desktop\python projects\tournament-generator\tournament-generator\cogs\Registration.py", line 38, in check_instance
    raise RegChannelSetupError
classes.Errors.RegChannelSetupError
2021-11-18 00:12:16,933 ERROR -> in command: nextround
Traceback (most recent call last):
  File "C:\Users\ryanz\AppData\Local\Programs\Python\Python39\lib\site-packages\discord\ext\commands\core.py", line 85, in wrapped
    ret = await coro(*args, **kwargs)
  File "c:\Users\ryanz\OneDrive\Desktop\python projects\tournament-generator\tournament-generator\cogs\Generation.py", line 180, in nextround
    mes, round, file_content = self.bot.generator_instances[ctx.channel.id].next_round()
  File "c:\Users\ryanz\OneDrive\Desktop\python projects\tournament-generator\tournament-generator\classes\Channels.py", line 125, in next_round
    registration_instance.update_round_results(self.generator.get_round_results())
  File "c:\Users\ryanz\OneDrive\Desktop\python projects\tournament-generator\tournament-generator\classes\generator.py", line 187, in get_round_results
    if round == -1: round = list(self.round_advancements.keys())[-1] #get last round's results
IndexError: list index out of range


2021-11-18 00:14:22,739 ERROR -> in command: nextround
Traceback (most recent call last):
  File "C:\Users\ryanz\AppData\Local\Programs\Python\Python39\lib\site-packages\discord\ext\commands\core.py", line 85, in wrapped
    ret = await coro(*args, **kwargs)
  File "c:\Users\ryanz\OneDrive\Desktop\python projects\tournament-generator\tournament-generator\cogs\Generation.py", line 180, in nextround
    mes, round, file_content = self.bot.generator_instances[ctx.channel.id].next_round()
  File "c:\Users\ryanz\OneDrive\Desktop\python projects\tournament-generator\tournament-generator\classes\Channels.py", line 126, in next_round
    registration_instance.update_round_results(self.generator.get_round_results())
  File "c:\Users\ryanz\OneDrive\Desktop\python projects\tournament-generator\tournament-generator\classes\Channels.py", line 45, in update_round_results
    self.registrator.add_round_results(results)
  File "c:\Users\ryanz\OneDrive\Desktop\python projects\tournament-generator\tournament-generator\classes\registrator.py", line 97, in add_round_results
    self.res_sheet.update(results_range, results_data)
  File "C:\Users\ryanz\AppData\Local\Programs\Python\Python39\lib\site-packages\gspread\utils.py", line 593, in wrapper
    return f(*args, **kwargs)
  File "C:\Users\ryanz\AppData\Local\Programs\Python\Python39\lib\site-packages\gspread\models.py", line 1276, in update
    response = self.spreadsheet.values_update(
  File "C:\Users\ryanz\AppData\Local\Programs\Python\Python39\lib\site-packages\gspread\models.py", line 265, in values_update
    r = self.client.request('put', url, params=params, json=body)
  File "C:\Users\ryanz\AppData\Local\Programs\Python\Python39\lib\site-packages\gspread\client.py", line 64, in request
    response = getattr(self.session, method)(
  File "C:\Users\ryanz\AppData\Local\Programs\Python\Python39\lib\site-packages\requests\sessions.py", line 602, in put
    return self.request('PUT', url, data=data, **kwargs)
  File "C:\Users\ryanz\AppData\Local\Programs\Python\Python39\lib\site-packages\google\auth\transport\requests.py", line 480, in request
    response = super(AuthorizedSession, self).request(
  File "C:\Users\ryanz\AppData\Local\Programs\Python\Python39\lib\site-packages\requests\sessions.py", line 528, in request
    prep = self.prepare_request(req)
  File "C:\Users\ryanz\AppData\Local\Programs\Python\Python39\lib\site-packages\requests\sessions.py", line 456, in prepare_request
    p.prepare(
  File "C:\Users\ryanz\AppData\Local\Programs\Python\Python39\lib\site-packages\requests\models.py", line 319, in prepare
    self.prepare_body(data, files, json)
  File "C:\Users\ryanz\AppData\Local\Programs\Python\Python39\lib\site-packages\requests\models.py", line 469, in prepare_body
    body = complexjson.dumps(json)
  File "C:\Users\ryanz\AppData\Local\Programs\Python\Python39\lib\json\__init__.py", line 231, in dumps
    return _default_encoder.encode(obj)
  File "C:\Users\ryanz\AppData\Local\Programs\Python\Python39\lib\json\encoder.py", line 199, in encode
    chunks = self.iterencode(o, _one_shot=True)
  File "C:\Users\ryanz\AppData\Local\Programs\Python\Python39\lib\json\encoder.py", line 257, in iterencode
    return _iterencode(o, 0)
  File "C:\Users\ryanz\AppData\Local\Programs\Python\Python39\lib\json\encoder.py", line 179, in default
    raise TypeError(f'Object of type {o.__class__.__name__} '
TypeError: Object of type Player is not JSON serializable


2021-11-18 00:26:51,936 ERROR -> in command: finish
Traceback (most recent call last):
  File "C:\Users\ryanz\AppData\Local\Programs\Python\Python39\lib\site-packages\discord\ext\commands\core.py", line 85, in wrapped
    ret = await coro(*args, **kwargs)
  File "c:\Users\ryanz\OneDrive\Desktop\python projects\tournament-generator\tournament-generator\cogs\Generation.py", line 219, in finish
    gen_instance.end_tournament()
AttributeError: 'GenChannel' object has no attribute 'end_tournament'


